INFO [senderos.signals:17] Hubo un intento de inicio de sesion invalido
ERROR [django.request:224] Internal Server Error: /dologin/
Traceback (most recent call last):
  File "/home/pepe/.local/lib/python3.8/site-packages/django/core/handlers/exception.py", line 47, in inner
    response = get_response(request)
  File "/home/pepe/.local/lib/python3.8/site-packages/django/core/handlers/base.py", line 181, in _get_response
    response = wrapped_callback(request, *callback_args, **callback_kwargs)
  File "/home/pepe/mii_ssbw/senderos/views.py", line 142, in dologin
    user2 = authenticate(
  File "/home/pepe/.local/lib/python3.8/site-packages/django/views/decorators/debug.py", line 42, in sensitive_variables_wrapper
    return func(*func_args, **func_kwargs)
  File "/home/pepe/.local/lib/python3.8/site-packages/django/contrib/auth/__init__.py", line 87, in authenticate
    user_login_failed.send(sender=__name__, credentials=_clean_credentials(credentials), request=request)
  File "/home/pepe/.local/lib/python3.8/site-packages/django/dispatch/dispatcher.py", line 180, in send
    return [
  File "/home/pepe/.local/lib/python3.8/site-packages/django/dispatch/dispatcher.py", line 181, in <listcomp>
    (receiver, receiver(signal=self, sender=sender, **named))
  File "/home/pepe/mii_ssbw/senderos/signals.py", line 18, in log_user_login_failed
    print('user {} logged in failed through page {}'.format(credentials.get('username'), request.META.get('HTTP_REFERER')))
AttributeError: 'NoneType' object has no attribute 'META'
ERROR [django.request:224] Internal Server Error: /dologin/
Traceback (most recent call last):
  File "/home/pepe/.local/lib/python3.8/site-packages/django/core/handlers/exception.py", line 47, in inner
    response = get_response(request)
  File "/home/pepe/.local/lib/python3.8/site-packages/django/core/handlers/base.py", line 181, in _get_response
    response = wrapped_callback(request, *callback_args, **callback_kwargs)
  File "/home/pepe/mii_ssbw/senderos/views.py", line 142, in dologin
    user2 = authenticate(
  File "/home/pepe/.local/lib/python3.8/site-packages/django/views/decorators/debug.py", line 42, in sensitive_variables_wrapper
    return func(*func_args, **func_kwargs)
  File "/home/pepe/.local/lib/python3.8/site-packages/django/contrib/auth/__init__.py", line 87, in authenticate
    user_login_failed.send(sender=__name__, credentials=_clean_credentials(credentials), request=request)
  File "/home/pepe/.local/lib/python3.8/site-packages/django/dispatch/dispatcher.py", line 180, in send
    return [
  File "/home/pepe/.local/lib/python3.8/site-packages/django/dispatch/dispatcher.py", line 181, in <listcomp>
    (receiver, receiver(signal=self, sender=sender, **named))
  File "/home/pepe/mii_ssbw/senderos/signals.py", line 18, in log_user_login_failed
    print('user {} logged in failed through page {}'.format(credentials.get('username'), request.META.get('HTTP_REFERER')))
AttributeError: 'NoneType' object has no attribute 'META'
ERROR [django.server:161] "POST /dologin/ HTTP/1.1" 500 86131
ERROR [django.server:161] "POST /dologin/ HTTP/1.1" 500 86131
INFO [senderos.signals:17] Hubo un intento de inicio de sesion invalido
ERROR [django.request:224] Internal Server Error: /dologin/
Traceback (most recent call last):
  File "/home/pepe/.local/lib/python3.8/site-packages/django/core/handlers/exception.py", line 47, in inner
    response = get_response(request)
  File "/home/pepe/.local/lib/python3.8/site-packages/django/core/handlers/base.py", line 181, in _get_response
    response = wrapped_callback(request, *callback_args, **callback_kwargs)
  File "/home/pepe/mii_ssbw/senderos/views.py", line 142, in dologin
    user2 = authenticate(
  File "/home/pepe/.local/lib/python3.8/site-packages/django/views/decorators/debug.py", line 42, in sensitive_variables_wrapper
    return func(*func_args, **func_kwargs)
  File "/home/pepe/.local/lib/python3.8/site-packages/django/contrib/auth/__init__.py", line 87, in authenticate
    user_login_failed.send(sender=__name__, credentials=_clean_credentials(credentials), request=request)
  File "/home/pepe/.local/lib/python3.8/site-packages/django/dispatch/dispatcher.py", line 180, in send
    return [
  File "/home/pepe/.local/lib/python3.8/site-packages/django/dispatch/dispatcher.py", line 181, in <listcomp>
    (receiver, receiver(signal=self, sender=sender, **named))
  File "/home/pepe/mii_ssbw/senderos/signals.py", line 18, in log_user_login_failed
    print('user {} logged in failed through page {}'.format(credentials.get('username'), request.META.get('HTTP_REFERER')))
AttributeError: 'NoneType' object has no attribute 'META'
ERROR [django.request:224] Internal Server Error: /dologin/
Traceback (most recent call last):
  File "/home/pepe/.local/lib/python3.8/site-packages/django/core/handlers/exception.py", line 47, in inner
    response = get_response(request)
  File "/home/pepe/.local/lib/python3.8/site-packages/django/core/handlers/base.py", line 181, in _get_response
    response = wrapped_callback(request, *callback_args, **callback_kwargs)
  File "/home/pepe/mii_ssbw/senderos/views.py", line 142, in dologin
    user2 = authenticate(
  File "/home/pepe/.local/lib/python3.8/site-packages/django/views/decorators/debug.py", line 42, in sensitive_variables_wrapper
    return func(*func_args, **func_kwargs)
  File "/home/pepe/.local/lib/python3.8/site-packages/django/contrib/auth/__init__.py", line 87, in authenticate
    user_login_failed.send(sender=__name__, credentials=_clean_credentials(credentials), request=request)
  File "/home/pepe/.local/lib/python3.8/site-packages/django/dispatch/dispatcher.py", line 180, in send
    return [
  File "/home/pepe/.local/lib/python3.8/site-packages/django/dispatch/dispatcher.py", line 181, in <listcomp>
    (receiver, receiver(signal=self, sender=sender, **named))
  File "/home/pepe/mii_ssbw/senderos/signals.py", line 18, in log_user_login_failed
    print('user {} logged in failed through page {}'.format(credentials.get('username'), request.META.get('HTTP_REFERER')))
AttributeError: 'NoneType' object has no attribute 'META'
ERROR [django.server:161] "POST /dologin/ HTTP/1.1" 500 86137
ERROR [django.server:161] "POST /dologin/ HTTP/1.1" 500 86137
INFO [senderos.signals:10] pepe@pepe.com ha iniciado sesion <WSGIRequest: POST '/dologin/'>
